[2022-11-16 01:37:23,356] {taskinstance.py:851} INFO - Dependencies all met for <TaskInstance: hello_world.hello_task 2022-04-02T00:00:00+00:00 [queued]>
[2022-11-16 01:37:23,750] {taskinstance.py:851} INFO - Dependencies all met for <TaskInstance: hello_world.hello_task 2022-04-02T00:00:00+00:00 [queued]>
[2022-11-16 01:37:23,776] {taskinstance.py:1042} INFO - 
--------------------------------------------------------------------------------
[2022-11-16 01:37:23,781] {taskinstance.py:1043} INFO - Starting attempt 1 of 1
[2022-11-16 01:37:23,789] {taskinstance.py:1044} INFO - 
--------------------------------------------------------------------------------
[2022-11-16 01:37:24,475] {taskinstance.py:1063} INFO - Executing <Task(PythonOperator): hello_task> on 2022-04-02T00:00:00+00:00
[2022-11-16 01:37:24,663] {standard_task_runner.py:52} INFO - Started process 541 to run task
[2022-11-16 01:37:24,832] {standard_task_runner.py:76} INFO - Running: ['airflow', 'tasks', 'run', 'hello_world', 'hello_task', '2022-04-02T00:00:00+00:00', '--job-id', '115', '--pool', 'default_pool', '--raw', '--subdir', 'DAGS_FOLDER/index.py', '--cfg-path', '/tmp/tmp63pcy_60', '--error-file', '/tmp/tmpwd3kpcrs']
[2022-11-16 01:37:24,850] {standard_task_runner.py:77} INFO - Job 115: Subtask hello_task
[2022-11-16 01:37:26,279] {logging_mixin.py:104} INFO - Running <TaskInstance: hello_world.hello_task 2022-04-02T00:00:00+00:00 [running]> on host 001906ffd7c9
[2022-11-16 01:37:27,374] {taskinstance.py:1257} INFO - Exporting the following env vars:
AIRFLOW_CTX_DAG_OWNER=airflow
AIRFLOW_CTX_DAG_ID=hello_world
AIRFLOW_CTX_TASK_ID=hello_task
AIRFLOW_CTX_EXECUTION_DATE=2022-04-02T00:00:00+00:00
AIRFLOW_CTX_DAG_RUN_ID=scheduled__2022-04-02T00:00:00+00:00
[2022-11-16 01:37:27,411] {taskinstance.py:1455} ERROR - run() takes 0 positional arguments but 1 was given
Traceback (most recent call last):
  File "/home/airflow/.local/lib/python3.6/site-packages/airflow/models/taskinstance.py", line 1112, in _run_raw_task
    self._prepare_and_execute_task_with_callbacks(context, task)
  File "/home/airflow/.local/lib/python3.6/site-packages/airflow/models/taskinstance.py", line 1285, in _prepare_and_execute_task_with_callbacks
    result = self._execute_task(context, task_copy)
  File "/home/airflow/.local/lib/python3.6/site-packages/airflow/models/taskinstance.py", line 1315, in _execute_task
    result = task_copy.execute(context=context)
  File "/home/airflow/.local/lib/python3.6/site-packages/airflow/operators/python.py", line 117, in execute
    return_value = self.execute_callable()
  File "/home/airflow/.local/lib/python3.6/site-packages/airflow/operators/python.py", line 128, in execute_callable
    return self.python_callable(*self.op_args, **self.op_kwargs)
  File "/opt/airflow/dags/index.py", line 9, in hello
    Client().run()
TypeError: run() takes 0 positional arguments but 1 was given
[2022-11-16 01:37:27,648] {taskinstance.py:1503} INFO - Marking task as FAILED. dag_id=hello_world, task_id=hello_task, execution_date=20220402T000000, start_date=20221116T013723, end_date=20221116T013727
[2022-11-16 01:37:29,024] {local_task_job.py:146} INFO - Task exited with return code 1
