[2022-11-16 01:42:21,454] {taskinstance.py:851} INFO - Dependencies all met for <TaskInstance: hello_world.hello_task 2022-09-01T00:00:00+00:00 [queued]>
[2022-11-16 01:42:21,581] {taskinstance.py:851} INFO - Dependencies all met for <TaskInstance: hello_world.hello_task 2022-09-01T00:00:00+00:00 [queued]>
[2022-11-16 01:42:21,584] {taskinstance.py:1042} INFO - 
--------------------------------------------------------------------------------
[2022-11-16 01:42:21,587] {taskinstance.py:1043} INFO - Starting attempt 1 of 1
[2022-11-16 01:42:21,589] {taskinstance.py:1044} INFO - 
--------------------------------------------------------------------------------
[2022-11-16 01:42:21,680] {taskinstance.py:1063} INFO - Executing <Task(PythonOperator): hello_task> on 2022-09-01T00:00:00+00:00
[2022-11-16 01:42:21,697] {standard_task_runner.py:52} INFO - Started process 1147 to run task
[2022-11-16 01:42:21,775] {standard_task_runner.py:76} INFO - Running: ['airflow', 'tasks', 'run', 'hello_world', 'hello_task', '2022-09-01T00:00:00+00:00', '--job-id', '267', '--pool', 'default_pool', '--raw', '--subdir', 'DAGS_FOLDER/index.py', '--cfg-path', '/tmp/tmpw0i0ffp4', '--error-file', '/tmp/tmpm67bim8_']
[2022-11-16 01:42:21,779] {standard_task_runner.py:77} INFO - Job 267: Subtask hello_task
[2022-11-16 01:42:22,485] {logging_mixin.py:104} INFO - Running <TaskInstance: hello_world.hello_task 2022-09-01T00:00:00+00:00 [running]> on host 001906ffd7c9
[2022-11-16 01:42:23,064] {taskinstance.py:1257} INFO - Exporting the following env vars:
AIRFLOW_CTX_DAG_OWNER=airflow
AIRFLOW_CTX_DAG_ID=hello_world
AIRFLOW_CTX_TASK_ID=hello_task
AIRFLOW_CTX_EXECUTION_DATE=2022-09-01T00:00:00+00:00
AIRFLOW_CTX_DAG_RUN_ID=scheduled__2022-09-01T00:00:00+00:00
[2022-11-16 01:42:23,103] {taskinstance.py:1455} ERROR - run() takes 0 positional arguments but 1 was given
Traceback (most recent call last):
  File "/home/airflow/.local/lib/python3.6/site-packages/airflow/models/taskinstance.py", line 1112, in _run_raw_task
    self._prepare_and_execute_task_with_callbacks(context, task)
  File "/home/airflow/.local/lib/python3.6/site-packages/airflow/models/taskinstance.py", line 1285, in _prepare_and_execute_task_with_callbacks
    result = self._execute_task(context, task_copy)
  File "/home/airflow/.local/lib/python3.6/site-packages/airflow/models/taskinstance.py", line 1315, in _execute_task
    result = task_copy.execute(context=context)
  File "/home/airflow/.local/lib/python3.6/site-packages/airflow/operators/python.py", line 117, in execute
    return_value = self.execute_callable()
  File "/home/airflow/.local/lib/python3.6/site-packages/airflow/operators/python.py", line 128, in execute_callable
    return self.python_callable(*self.op_args, **self.op_kwargs)
  File "/opt/airflow/dags/index.py", line 9, in hello
    Client().run()
TypeError: run() takes 0 positional arguments but 1 was given
[2022-11-16 01:42:23,247] {taskinstance.py:1503} INFO - Marking task as FAILED. dag_id=hello_world, task_id=hello_task, execution_date=20220901T000000, start_date=20221116T014221, end_date=20221116T014223
[2022-11-16 01:42:23,667] {local_task_job.py:146} INFO - Task exited with return code 1
