[2022-11-16 01:38:21,484] {taskinstance.py:851} INFO - Dependencies all met for <TaskInstance: hello_world.hello_task 2022-04-21T00:00:00+00:00 [queued]>
[2022-11-16 01:38:21,796] {taskinstance.py:851} INFO - Dependencies all met for <TaskInstance: hello_world.hello_task 2022-04-21T00:00:00+00:00 [queued]>
[2022-11-16 01:38:21,812] {taskinstance.py:1042} INFO - 
--------------------------------------------------------------------------------
[2022-11-16 01:38:21,816] {taskinstance.py:1043} INFO - Starting attempt 1 of 1
[2022-11-16 01:38:21,820] {taskinstance.py:1044} INFO - 
--------------------------------------------------------------------------------
[2022-11-16 01:38:22,223] {taskinstance.py:1063} INFO - Executing <Task(PythonOperator): hello_task> on 2022-04-21T00:00:00+00:00
[2022-11-16 01:38:22,294] {standard_task_runner.py:52} INFO - Started process 617 to run task
[2022-11-16 01:38:22,749] {standard_task_runner.py:76} INFO - Running: ['airflow', 'tasks', 'run', 'hello_world', 'hello_task', '2022-04-21T00:00:00+00:00', '--job-id', '134', '--pool', 'default_pool', '--raw', '--subdir', 'DAGS_FOLDER/index.py', '--cfg-path', '/tmp/tmpif1a0sk5', '--error-file', '/tmp/tmpk1n7iws8']
[2022-11-16 01:38:22,870] {standard_task_runner.py:77} INFO - Job 134: Subtask hello_task
[2022-11-16 01:38:25,362] {logging_mixin.py:104} INFO - Running <TaskInstance: hello_world.hello_task 2022-04-21T00:00:00+00:00 [running]> on host 001906ffd7c9
[2022-11-16 01:38:26,360] {taskinstance.py:1257} INFO - Exporting the following env vars:
AIRFLOW_CTX_DAG_OWNER=airflow
AIRFLOW_CTX_DAG_ID=hello_world
AIRFLOW_CTX_TASK_ID=hello_task
AIRFLOW_CTX_EXECUTION_DATE=2022-04-21T00:00:00+00:00
AIRFLOW_CTX_DAG_RUN_ID=scheduled__2022-04-21T00:00:00+00:00
[2022-11-16 01:38:26,414] {taskinstance.py:1455} ERROR - run() takes 0 positional arguments but 1 was given
Traceback (most recent call last):
  File "/home/airflow/.local/lib/python3.6/site-packages/airflow/models/taskinstance.py", line 1112, in _run_raw_task
    self._prepare_and_execute_task_with_callbacks(context, task)
  File "/home/airflow/.local/lib/python3.6/site-packages/airflow/models/taskinstance.py", line 1285, in _prepare_and_execute_task_with_callbacks
    result = self._execute_task(context, task_copy)
  File "/home/airflow/.local/lib/python3.6/site-packages/airflow/models/taskinstance.py", line 1315, in _execute_task
    result = task_copy.execute(context=context)
  File "/home/airflow/.local/lib/python3.6/site-packages/airflow/operators/python.py", line 117, in execute
    return_value = self.execute_callable()
  File "/home/airflow/.local/lib/python3.6/site-packages/airflow/operators/python.py", line 128, in execute_callable
    return self.python_callable(*self.op_args, **self.op_kwargs)
  File "/opt/airflow/dags/index.py", line 9, in hello
    Client().run()
TypeError: run() takes 0 positional arguments but 1 was given
[2022-11-16 01:38:26,527] {taskinstance.py:1503} INFO - Marking task as FAILED. dag_id=hello_world, task_id=hello_task, execution_date=20220421T000000, start_date=20221116T013821, end_date=20221116T013826
[2022-11-16 01:38:27,139] {local_task_job.py:146} INFO - Task exited with return code 1
